2022-07-19 13:57:22,226 (DEBUG): Starting new HTTPS connection (1): hotelapi.loyalty.dev:443
2022-07-19 13:57:22,260 (ERROR): Exception in ASGI application
Traceback (most recent call last):
  File "C:\Users\Razer\AppData\Local\Programs\Python\Python310\lib\site-packages\urllib3\connection.py", line 174, in _new_conn
    conn = connection.create_connection(
  File "C:\Users\Razer\AppData\Local\Programs\Python\Python310\lib\site-packages\urllib3\util\connection.py", line 72, in create_connection
    for res in socket.getaddrinfo(host, port, family, socket.SOCK_STREAM):
  File "C:\Users\Razer\AppData\Local\Programs\Python\Python310\lib\socket.py", line 955, in getaddrinfo
    for res in _socket.getaddrinfo(host, port, family, type, proto, flags):
socket.gaierror: [Errno 11001] getaddrinfo failed

During handling of the above exception, another exception occurred:

Traceback (most recent call last):
  File "C:\Users\Razer\AppData\Local\Programs\Python\Python310\lib\site-packages\urllib3\connectionpool.py", line 703, in urlopen
    httplib_response = self._make_request(
  File "C:\Users\Razer\AppData\Local\Programs\Python\Python310\lib\site-packages\urllib3\connectionpool.py", line 386, in _make_request
    self._validate_conn(conn)
  File "C:\Users\Razer\AppData\Local\Programs\Python\Python310\lib\site-packages\urllib3\connectionpool.py", line 1040, in _validate_conn
    conn.connect()
  File "C:\Users\Razer\AppData\Local\Programs\Python\Python310\lib\site-packages\urllib3\connection.py", line 358, in connect
    self.sock = conn = self._new_conn()
  File "C:\Users\Razer\AppData\Local\Programs\Python\Python310\lib\site-packages\urllib3\connection.py", line 186, in _new_conn
    raise NewConnectionError(
urllib3.exceptions.NewConnectionError: <urllib3.connection.HTTPSConnection object at 0x000001F65FFEA3B0>: Failed to establish a new connection: [Errno 11001] getaddrinfo failed

During handling of the above exception, another exception occurred:

Traceback (most recent call last):
  File "C:\Users\Razer\AppData\Local\Programs\Python\Python310\lib\site-packages\requests\adapters.py", line 440, in send
    resp = conn.urlopen(
  File "C:\Users\Razer\AppData\Local\Programs\Python\Python310\lib\site-packages\urllib3\connectionpool.py", line 785, in urlopen
    retries = retries.increment(
  File "C:\Users\Razer\AppData\Local\Programs\Python\Python310\lib\site-packages\urllib3\util\retry.py", line 592, in increment
    raise MaxRetryError(_pool, url, error or ResponseError(cause))
urllib3.exceptions.MaxRetryError: HTTPSConnectionPool(host='hotelapi.loyalty.dev', port=443): Max retries exceeded with url: /api/hotels/Jot8 (Caused by NewConnectionError('<urllib3.connection.HTTPSConnection object at 0x000001F65FFEA3B0>: Failed to establish a new connection: [Errno 11001] getaddrinfo failed'))

During handling of the above exception, another exception occurred:

Traceback (most recent call last):
  File "C:\Users\Razer\AppData\Local\Programs\Python\Python310\lib\site-packages\uvicorn\protocols\http\h11_impl.py", line 366, in run_asgi
    result = await app(self.scope, self.receive, self.send)
  File "C:\Users\Razer\AppData\Local\Programs\Python\Python310\lib\site-packages\uvicorn\middleware\proxy_headers.py", line 75, in __call__
    return await self.app(scope, receive, send)
  File "C:\Users\Razer\AppData\Local\Programs\Python\Python310\lib\site-packages\fastapi\applications.py", line 261, in __call__
    await super().__call__(scope, receive, send)
  File "C:\Users\Razer\AppData\Local\Programs\Python\Python310\lib\site-packages\starlette\applications.py", line 112, in __call__
    await self.middleware_stack(scope, receive, send)
  File "C:\Users\Razer\AppData\Local\Programs\Python\Python310\lib\site-packages\starlette\middleware\errors.py", line 181, in __call__
    raise exc
  File "C:\Users\Razer\AppData\Local\Programs\Python\Python310\lib\site-packages\starlette\middleware\errors.py", line 159, in __call__
    await self.app(scope, receive, _send)
  File "C:\Users\Razer\AppData\Local\Programs\Python\Python310\lib\site-packages\starlette\middleware\cors.py", line 92, in __call__
    await self.simple_response(scope, receive, send, request_headers=headers)
  File "C:\Users\Razer\AppData\Local\Programs\Python\Python310\lib\site-packages\starlette\middleware\cors.py", line 147, in simple_response
    await self.app(scope, receive, send)
  File "C:\Users\Razer\AppData\Local\Programs\Python\Python310\lib\site-packages\starlette\exceptions.py", line 82, in __call__
    raise exc
  File "C:\Users\Razer\AppData\Local\Programs\Python\Python310\lib\site-packages\starlette\exceptions.py", line 71, in __call__
    await self.app(scope, receive, sender)
  File "C:\Users\Razer\AppData\Local\Programs\Python\Python310\lib\site-packages\fastapi\middleware\asyncexitstack.py", line 21, in __call__
    raise e
  File "C:\Users\Razer\AppData\Local\Programs\Python\Python310\lib\site-packages\fastapi\middleware\asyncexitstack.py", line 18, in __call__
    await self.app(scope, receive, send)
  File "C:\Users\Razer\AppData\Local\Programs\Python\Python310\lib\site-packages\starlette\routing.py", line 656, in __call__
    await route.handle(scope, receive, send)
  File "C:\Users\Razer\AppData\Local\Programs\Python\Python310\lib\site-packages\starlette\routing.py", line 259, in handle
    await self.app(scope, receive, send)
  File "C:\Users\Razer\AppData\Local\Programs\Python\Python310\lib\site-packages\starlette\routing.py", line 61, in app
    response = await func(request)
  File "C:\Users\Razer\AppData\Local\Programs\Python\Python310\lib\site-packages\fastapi\routing.py", line 227, in app
    raw_response = await run_endpoint_function(
  File "C:\Users\Razer\AppData\Local\Programs\Python\Python310\lib\site-packages\fastapi\routing.py", line 162, in run_endpoint_function
    return await run_in_threadpool(dependant.call, **values)
  File "C:\Users\Razer\AppData\Local\Programs\Python\Python310\lib\site-packages\starlette\concurrency.py", line 39, in run_in_threadpool
    return await anyio.to_thread.run_sync(func, *args)
  File "C:\Users\Razer\AppData\Local\Programs\Python\Python310\lib\site-packages\anyio\to_thread.py", line 28, in run_sync
    return await get_asynclib().run_sync_in_worker_thread(func, *args, cancellable=cancellable,
  File "C:\Users\Razer\AppData\Local\Programs\Python\Python310\lib\site-packages\anyio\_backends\_asyncio.py", line 818, in run_sync_in_worker_thread
    return await future
  File "C:\Users\Razer\AppData\Local\Programs\Python\Python310\lib\site-packages\anyio\_backends\_asyncio.py", line 754, in run
    result = context.run(func, *args)
  File "C:\Users\Razer\Documents\GitHub\c5g8_esc\.\backend\routers\hotel.py", line 32, in serve_hotels
    hotel := database.generate_hotel(
  File "C:\Users\Razer\Documents\GitHub\c5g8_esc\.\backend\core\models\database.py", line 181, in generate_hotel
    hotel = requests.get(get_hotel_endpoint(hotel_id))
  File "C:\Users\Razer\AppData\Local\Programs\Python\Python310\lib\site-packages\requests\api.py", line 75, in get
    return request('get', url, params=params, **kwargs)
  File "C:\Users\Razer\AppData\Local\Programs\Python\Python310\lib\site-packages\requests\api.py", line 61, in request
    return session.request(method=method, url=url, **kwargs)
  File "C:\Users\Razer\AppData\Local\Programs\Python\Python310\lib\site-packages\requests\sessions.py", line 529, in request
    resp = self.send(prep, **send_kwargs)
  File "C:\Users\Razer\AppData\Local\Programs\Python\Python310\lib\site-packages\requests\sessions.py", line 645, in send
    r = adapter.send(request, **kwargs)
  File "C:\Users\Razer\AppData\Local\Programs\Python\Python310\lib\site-packages\requests\adapters.py", line 519, in send
    raise ConnectionError(e, request=request)
requests.exceptions.ConnectionError: HTTPSConnectionPool(host='hotelapi.loyalty.dev', port=443): Max retries exceeded with url: /api/hotels/Jot8 (Caused by NewConnectionError('<urllib3.connection.HTTPSConnection object at 0x000001F65FFEA3B0>: Failed to establish a new connection: [Errno 11001] getaddrinfo failed'))
2022-07-19 13:57:46,898 (DEBUG): Starting new HTTPS connection (1): hotelapi.loyalty.dev:443
2022-07-19 13:57:46,900 (ERROR): Exception in ASGI application
Traceback (most recent call last):
  File "C:\Users\Razer\AppData\Local\Programs\Python\Python310\lib\site-packages\urllib3\connection.py", line 174, in _new_conn
    conn = connection.create_connection(
  File "C:\Users\Razer\AppData\Local\Programs\Python\Python310\lib\site-packages\urllib3\util\connection.py", line 72, in create_connection
    for res in socket.getaddrinfo(host, port, family, socket.SOCK_STREAM):
  File "C:\Users\Razer\AppData\Local\Programs\Python\Python310\lib\socket.py", line 955, in getaddrinfo
    for res in _socket.getaddrinfo(host, port, family, type, proto, flags):
socket.gaierror: [Errno 11001] getaddrinfo failed

During handling of the above exception, another exception occurred:

Traceback (most recent call last):
  File "C:\Users\Razer\AppData\Local\Programs\Python\Python310\lib\site-packages\urllib3\connectionpool.py", line 703, in urlopen
    httplib_response = self._make_request(
  File "C:\Users\Razer\AppData\Local\Programs\Python\Python310\lib\site-packages\urllib3\connectionpool.py", line 386, in _make_request
    self._validate_conn(conn)
  File "C:\Users\Razer\AppData\Local\Programs\Python\Python310\lib\site-packages\urllib3\connectionpool.py", line 1040, in _validate_conn
    conn.connect()
  File "C:\Users\Razer\AppData\Local\Programs\Python\Python310\lib\site-packages\urllib3\connection.py", line 358, in connect
    self.sock = conn = self._new_conn()
  File "C:\Users\Razer\AppData\Local\Programs\Python\Python310\lib\site-packages\urllib3\connection.py", line 186, in _new_conn
    raise NewConnectionError(
urllib3.exceptions.NewConnectionError: <urllib3.connection.HTTPSConnection object at 0x000001F6603E1180>: Failed to establish a new connection: [Errno 11001] getaddrinfo failed

During handling of the above exception, another exception occurred:

Traceback (most recent call last):
  File "C:\Users\Razer\AppData\Local\Programs\Python\Python310\lib\site-packages\requests\adapters.py", line 440, in send
    resp = conn.urlopen(
  File "C:\Users\Razer\AppData\Local\Programs\Python\Python310\lib\site-packages\urllib3\connectionpool.py", line 785, in urlopen
    retries = retries.increment(
  File "C:\Users\Razer\AppData\Local\Programs\Python\Python310\lib\site-packages\urllib3\util\retry.py", line 592, in increment
    raise MaxRetryError(_pool, url, error or ResponseError(cause))
urllib3.exceptions.MaxRetryError: HTTPSConnectionPool(host='hotelapi.loyalty.dev', port=443): Max retries exceeded with url: /api/hotels/Jot8 (Caused by NewConnectionError('<urllib3.connection.HTTPSConnection object at 0x000001F6603E1180>: Failed to establish a new connection: [Errno 11001] getaddrinfo failed'))

During handling of the above exception, another exception occurred:

Traceback (most recent call last):
  File "C:\Users\Razer\AppData\Local\Programs\Python\Python310\lib\site-packages\uvicorn\protocols\http\h11_impl.py", line 366, in run_asgi
    result = await app(self.scope, self.receive, self.send)
  File "C:\Users\Razer\AppData\Local\Programs\Python\Python310\lib\site-packages\uvicorn\middleware\proxy_headers.py", line 75, in __call__
    return await self.app(scope, receive, send)
  File "C:\Users\Razer\AppData\Local\Programs\Python\Python310\lib\site-packages\fastapi\applications.py", line 261, in __call__
    await super().__call__(scope, receive, send)
  File "C:\Users\Razer\AppData\Local\Programs\Python\Python310\lib\site-packages\starlette\applications.py", line 112, in __call__
    await self.middleware_stack(scope, receive, send)
  File "C:\Users\Razer\AppData\Local\Programs\Python\Python310\lib\site-packages\starlette\middleware\errors.py", line 181, in __call__
    raise exc
  File "C:\Users\Razer\AppData\Local\Programs\Python\Python310\lib\site-packages\starlette\middleware\errors.py", line 159, in __call__
    await self.app(scope, receive, _send)
  File "C:\Users\Razer\AppData\Local\Programs\Python\Python310\lib\site-packages\starlette\middleware\cors.py", line 92, in __call__
    await self.simple_response(scope, receive, send, request_headers=headers)
  File "C:\Users\Razer\AppData\Local\Programs\Python\Python310\lib\site-packages\starlette\middleware\cors.py", line 147, in simple_response
    await self.app(scope, receive, send)
  File "C:\Users\Razer\AppData\Local\Programs\Python\Python310\lib\site-packages\starlette\exceptions.py", line 82, in __call__
    raise exc
  File "C:\Users\Razer\AppData\Local\Programs\Python\Python310\lib\site-packages\starlette\exceptions.py", line 71, in __call__
    await self.app(scope, receive, sender)
  File "C:\Users\Razer\AppData\Local\Programs\Python\Python310\lib\site-packages\fastapi\middleware\asyncexitstack.py", line 21, in __call__
    raise e
  File "C:\Users\Razer\AppData\Local\Programs\Python\Python310\lib\site-packages\fastapi\middleware\asyncexitstack.py", line 18, in __call__
    await self.app(scope, receive, send)
  File "C:\Users\Razer\AppData\Local\Programs\Python\Python310\lib\site-packages\starlette\routing.py", line 656, in __call__
    await route.handle(scope, receive, send)
  File "C:\Users\Razer\AppData\Local\Programs\Python\Python310\lib\site-packages\starlette\routing.py", line 259, in handle
    await self.app(scope, receive, send)
  File "C:\Users\Razer\AppData\Local\Programs\Python\Python310\lib\site-packages\starlette\routing.py", line 61, in app
    response = await func(request)
  File "C:\Users\Razer\AppData\Local\Programs\Python\Python310\lib\site-packages\fastapi\routing.py", line 227, in app
    raw_response = await run_endpoint_function(
  File "C:\Users\Razer\AppData\Local\Programs\Python\Python310\lib\site-packages\fastapi\routing.py", line 162, in run_endpoint_function
    return await run_in_threadpool(dependant.call, **values)
  File "C:\Users\Razer\AppData\Local\Programs\Python\Python310\lib\site-packages\starlette\concurrency.py", line 39, in run_in_threadpool
    return await anyio.to_thread.run_sync(func, *args)
  File "C:\Users\Razer\AppData\Local\Programs\Python\Python310\lib\site-packages\anyio\to_thread.py", line 28, in run_sync
    return await get_asynclib().run_sync_in_worker_thread(func, *args, cancellable=cancellable,
  File "C:\Users\Razer\AppData\Local\Programs\Python\Python310\lib\site-packages\anyio\_backends\_asyncio.py", line 818, in run_sync_in_worker_thread
    return await future
  File "C:\Users\Razer\AppData\Local\Programs\Python\Python310\lib\site-packages\anyio\_backends\_asyncio.py", line 754, in run
    result = context.run(func, *args)
  File "C:\Users\Razer\Documents\GitHub\c5g8_esc\.\backend\routers\hotel.py", line 32, in serve_hotels
    hotel := database.generate_hotel(
  File "C:\Users\Razer\Documents\GitHub\c5g8_esc\.\backend\core\models\database.py", line 181, in generate_hotel
    hotel = requests.get(get_hotel_endpoint(hotel_id))
  File "C:\Users\Razer\AppData\Local\Programs\Python\Python310\lib\site-packages\requests\api.py", line 75, in get
    return request('get', url, params=params, **kwargs)
  File "C:\Users\Razer\AppData\Local\Programs\Python\Python310\lib\site-packages\requests\api.py", line 61, in request
    return session.request(method=method, url=url, **kwargs)
  File "C:\Users\Razer\AppData\Local\Programs\Python\Python310\lib\site-packages\requests\sessions.py", line 529, in request
    resp = self.send(prep, **send_kwargs)
  File "C:\Users\Razer\AppData\Local\Programs\Python\Python310\lib\site-packages\requests\sessions.py", line 645, in send
    r = adapter.send(request, **kwargs)
  File "C:\Users\Razer\AppData\Local\Programs\Python\Python310\lib\site-packages\requests\adapters.py", line 519, in send
    raise ConnectionError(e, request=request)
requests.exceptions.ConnectionError: HTTPSConnectionPool(host='hotelapi.loyalty.dev', port=443): Max retries exceeded with url: /api/hotels/Jot8 (Caused by NewConnectionError('<urllib3.connection.HTTPSConnection object at 0x000001F6603E1180>: Failed to establish a new connection: [Errno 11001] getaddrinfo failed'))
2022-07-19 13:57:51,184 (DEBUG): Starting new HTTPS connection (1): hotelapi.loyalty.dev:443
2022-07-19 13:57:51,189 (ERROR): Exception in ASGI application
Traceback (most recent call last):
  File "C:\Users\Razer\AppData\Local\Programs\Python\Python310\lib\site-packages\urllib3\connection.py", line 174, in _new_conn
    conn = connection.create_connection(
  File "C:\Users\Razer\AppData\Local\Programs\Python\Python310\lib\site-packages\urllib3\util\connection.py", line 72, in create_connection
    for res in socket.getaddrinfo(host, port, family, socket.SOCK_STREAM):
  File "C:\Users\Razer\AppData\Local\Programs\Python\Python310\lib\socket.py", line 955, in getaddrinfo
    for res in _socket.getaddrinfo(host, port, family, type, proto, flags):
socket.gaierror: [Errno 11001] getaddrinfo failed

During handling of the above exception, another exception occurred:

Traceback (most recent call last):
  File "C:\Users\Razer\AppData\Local\Programs\Python\Python310\lib\site-packages\urllib3\connectionpool.py", line 703, in urlopen
    httplib_response = self._make_request(
  File "C:\Users\Razer\AppData\Local\Programs\Python\Python310\lib\site-packages\urllib3\connectionpool.py", line 386, in _make_request
    self._validate_conn(conn)
  File "C:\Users\Razer\AppData\Local\Programs\Python\Python310\lib\site-packages\urllib3\connectionpool.py", line 1040, in _validate_conn
    conn.connect()
  File "C:\Users\Razer\AppData\Local\Programs\Python\Python310\lib\site-packages\urllib3\connection.py", line 358, in connect
    self.sock = conn = self._new_conn()
  File "C:\Users\Razer\AppData\Local\Programs\Python\Python310\lib\site-packages\urllib3\connection.py", line 186, in _new_conn
    raise NewConnectionError(
urllib3.exceptions.NewConnectionError: <urllib3.connection.HTTPSConnection object at 0x000001F6603E1660>: Failed to establish a new connection: [Errno 11001] getaddrinfo failed

During handling of the above exception, another exception occurred:

Traceback (most recent call last):
  File "C:\Users\Razer\AppData\Local\Programs\Python\Python310\lib\site-packages\requests\adapters.py", line 440, in send
    resp = conn.urlopen(
  File "C:\Users\Razer\AppData\Local\Programs\Python\Python310\lib\site-packages\urllib3\connectionpool.py", line 785, in urlopen
    retries = retries.increment(
  File "C:\Users\Razer\AppData\Local\Programs\Python\Python310\lib\site-packages\urllib3\util\retry.py", line 592, in increment
    raise MaxRetryError(_pool, url, error or ResponseError(cause))
urllib3.exceptions.MaxRetryError: HTTPSConnectionPool(host='hotelapi.loyalty.dev', port=443): Max retries exceeded with url: /api/hotels/Jot8 (Caused by NewConnectionError('<urllib3.connection.HTTPSConnection object at 0x000001F6603E1660>: Failed to establish a new connection: [Errno 11001] getaddrinfo failed'))

During handling of the above exception, another exception occurred:

Traceback (most recent call last):
  File "C:\Users\Razer\AppData\Local\Programs\Python\Python310\lib\site-packages\uvicorn\protocols\http\h11_impl.py", line 366, in run_asgi
    result = await app(self.scope, self.receive, self.send)
  File "C:\Users\Razer\AppData\Local\Programs\Python\Python310\lib\site-packages\uvicorn\middleware\proxy_headers.py", line 75, in __call__
    return await self.app(scope, receive, send)
  File "C:\Users\Razer\AppData\Local\Programs\Python\Python310\lib\site-packages\fastapi\applications.py", line 261, in __call__
    await super().__call__(scope, receive, send)
  File "C:\Users\Razer\AppData\Local\Programs\Python\Python310\lib\site-packages\starlette\applications.py", line 112, in __call__
    await self.middleware_stack(scope, receive, send)
  File "C:\Users\Razer\AppData\Local\Programs\Python\Python310\lib\site-packages\starlette\middleware\errors.py", line 181, in __call__
    raise exc
  File "C:\Users\Razer\AppData\Local\Programs\Python\Python310\lib\site-packages\starlette\middleware\errors.py", line 159, in __call__
    await self.app(scope, receive, _send)
  File "C:\Users\Razer\AppData\Local\Programs\Python\Python310\lib\site-packages\starlette\middleware\cors.py", line 92, in __call__
    await self.simple_response(scope, receive, send, request_headers=headers)
  File "C:\Users\Razer\AppData\Local\Programs\Python\Python310\lib\site-packages\starlette\middleware\cors.py", line 147, in simple_response
    await self.app(scope, receive, send)
  File "C:\Users\Razer\AppData\Local\Programs\Python\Python310\lib\site-packages\starlette\exceptions.py", line 82, in __call__
    raise exc
  File "C:\Users\Razer\AppData\Local\Programs\Python\Python310\lib\site-packages\starlette\exceptions.py", line 71, in __call__
    await self.app(scope, receive, sender)
  File "C:\Users\Razer\AppData\Local\Programs\Python\Python310\lib\site-packages\fastapi\middleware\asyncexitstack.py", line 21, in __call__
    raise e
  File "C:\Users\Razer\AppData\Local\Programs\Python\Python310\lib\site-packages\fastapi\middleware\asyncexitstack.py", line 18, in __call__
    await self.app(scope, receive, send)
  File "C:\Users\Razer\AppData\Local\Programs\Python\Python310\lib\site-packages\starlette\routing.py", line 656, in __call__
    await route.handle(scope, receive, send)
  File "C:\Users\Razer\AppData\Local\Programs\Python\Python310\lib\site-packages\starlette\routing.py", line 259, in handle
    await self.app(scope, receive, send)
  File "C:\Users\Razer\AppData\Local\Programs\Python\Python310\lib\site-packages\starlette\routing.py", line 61, in app
    response = await func(request)
  File "C:\Users\Razer\AppData\Local\Programs\Python\Python310\lib\site-packages\fastapi\routing.py", line 227, in app
    raw_response = await run_endpoint_function(
  File "C:\Users\Razer\AppData\Local\Programs\Python\Python310\lib\site-packages\fastapi\routing.py", line 162, in run_endpoint_function
    return await run_in_threadpool(dependant.call, **values)
  File "C:\Users\Razer\AppData\Local\Programs\Python\Python310\lib\site-packages\starlette\concurrency.py", line 39, in run_in_threadpool
    return await anyio.to_thread.run_sync(func, *args)
  File "C:\Users\Razer\AppData\Local\Programs\Python\Python310\lib\site-packages\anyio\to_thread.py", line 28, in run_sync
    return await get_asynclib().run_sync_in_worker_thread(func, *args, cancellable=cancellable,
  File "C:\Users\Razer\AppData\Local\Programs\Python\Python310\lib\site-packages\anyio\_backends\_asyncio.py", line 818, in run_sync_in_worker_thread
    return await future
  File "C:\Users\Razer\AppData\Local\Programs\Python\Python310\lib\site-packages\anyio\_backends\_asyncio.py", line 754, in run
    result = context.run(func, *args)
  File "C:\Users\Razer\Documents\GitHub\c5g8_esc\.\backend\routers\hotel.py", line 32, in serve_hotels
    hotel := database.generate_hotel(
  File "C:\Users\Razer\Documents\GitHub\c5g8_esc\.\backend\core\models\database.py", line 181, in generate_hotel
    hotel = requests.get(get_hotel_endpoint(hotel_id))
  File "C:\Users\Razer\AppData\Local\Programs\Python\Python310\lib\site-packages\requests\api.py", line 75, in get
    return request('get', url, params=params, **kwargs)
  File "C:\Users\Razer\AppData\Local\Programs\Python\Python310\lib\site-packages\requests\api.py", line 61, in request
    return session.request(method=method, url=url, **kwargs)
  File "C:\Users\Razer\AppData\Local\Programs\Python\Python310\lib\site-packages\requests\sessions.py", line 529, in request
    resp = self.send(prep, **send_kwargs)
  File "C:\Users\Razer\AppData\Local\Programs\Python\Python310\lib\site-packages\requests\sessions.py", line 645, in send
    r = adapter.send(request, **kwargs)
  File "C:\Users\Razer\AppData\Local\Programs\Python\Python310\lib\site-packages\requests\adapters.py", line 519, in send
    raise ConnectionError(e, request=request)
requests.exceptions.ConnectionError: HTTPSConnectionPool(host='hotelapi.loyalty.dev', port=443): Max retries exceeded with url: /api/hotels/Jot8 (Caused by NewConnectionError('<urllib3.connection.HTTPSConnection object at 0x000001F6603E1660>: Failed to establish a new connection: [Errno 11001] getaddrinfo failed'))
2022-07-19 13:57:59,899 (DEBUG): Starting new HTTPS connection (1): hotelapi.loyalty.dev:443
2022-07-19 13:57:59,901 (ERROR): Exception in ASGI application
Traceback (most recent call last):
  File "C:\Users\Razer\AppData\Local\Programs\Python\Python310\lib\site-packages\urllib3\connection.py", line 174, in _new_conn
    conn = connection.create_connection(
  File "C:\Users\Razer\AppData\Local\Programs\Python\Python310\lib\site-packages\urllib3\util\connection.py", line 72, in create_connection
    for res in socket.getaddrinfo(host, port, family, socket.SOCK_STREAM):
  File "C:\Users\Razer\AppData\Local\Programs\Python\Python310\lib\socket.py", line 955, in getaddrinfo
    for res in _socket.getaddrinfo(host, port, family, type, proto, flags):
socket.gaierror: [Errno 11001] getaddrinfo failed

During handling of the above exception, another exception occurred:

Traceback (most recent call last):
  File "C:\Users\Razer\AppData\Local\Programs\Python\Python310\lib\site-packages\urllib3\connectionpool.py", line 703, in urlopen
    httplib_response = self._make_request(
  File "C:\Users\Razer\AppData\Local\Programs\Python\Python310\lib\site-packages\urllib3\connectionpool.py", line 386, in _make_request
    self._validate_conn(conn)
  File "C:\Users\Razer\AppData\Local\Programs\Python\Python310\lib\site-packages\urllib3\connectionpool.py", line 1040, in _validate_conn
    conn.connect()
  File "C:\Users\Razer\AppData\Local\Programs\Python\Python310\lib\site-packages\urllib3\connection.py", line 358, in connect
    self.sock = conn = self._new_conn()
  File "C:\Users\Razer\AppData\Local\Programs\Python\Python310\lib\site-packages\urllib3\connection.py", line 186, in _new_conn
    raise NewConnectionError(
urllib3.exceptions.NewConnectionError: <urllib3.connection.HTTPSConnection object at 0x000001F6603E38B0>: Failed to establish a new connection: [Errno 11001] getaddrinfo failed

During handling of the above exception, another exception occurred:

Traceback (most recent call last):
  File "C:\Users\Razer\AppData\Local\Programs\Python\Python310\lib\site-packages\requests\adapters.py", line 440, in send
    resp = conn.urlopen(
  File "C:\Users\Razer\AppData\Local\Programs\Python\Python310\lib\site-packages\urllib3\connectionpool.py", line 785, in urlopen
    retries = retries.increment(
  File "C:\Users\Razer\AppData\Local\Programs\Python\Python310\lib\site-packages\urllib3\util\retry.py", line 592, in increment
    raise MaxRetryError(_pool, url, error or ResponseError(cause))
urllib3.exceptions.MaxRetryError: HTTPSConnectionPool(host='hotelapi.loyalty.dev', port=443): Max retries exceeded with url: /api/hotels/Jot8 (Caused by NewConnectionError('<urllib3.connection.HTTPSConnection object at 0x000001F6603E38B0>: Failed to establish a new connection: [Errno 11001] getaddrinfo failed'))

During handling of the above exception, another exception occurred:

Traceback (most recent call last):
  File "C:\Users\Razer\AppData\Local\Programs\Python\Python310\lib\site-packages\uvicorn\protocols\http\h11_impl.py", line 366, in run_asgi
    result = await app(self.scope, self.receive, self.send)
  File "C:\Users\Razer\AppData\Local\Programs\Python\Python310\lib\site-packages\uvicorn\middleware\proxy_headers.py", line 75, in __call__
    return await self.app(scope, receive, send)
  File "C:\Users\Razer\AppData\Local\Programs\Python\Python310\lib\site-packages\fastapi\applications.py", line 261, in __call__
    await super().__call__(scope, receive, send)
  File "C:\Users\Razer\AppData\Local\Programs\Python\Python310\lib\site-packages\starlette\applications.py", line 112, in __call__
    await self.middleware_stack(scope, receive, send)
  File "C:\Users\Razer\AppData\Local\Programs\Python\Python310\lib\site-packages\starlette\middleware\errors.py", line 181, in __call__
    raise exc
  File "C:\Users\Razer\AppData\Local\Programs\Python\Python310\lib\site-packages\starlette\middleware\errors.py", line 159, in __call__
    await self.app(scope, receive, _send)
  File "C:\Users\Razer\AppData\Local\Programs\Python\Python310\lib\site-packages\starlette\middleware\cors.py", line 92, in __call__
    await self.simple_response(scope, receive, send, request_headers=headers)
  File "C:\Users\Razer\AppData\Local\Programs\Python\Python310\lib\site-packages\starlette\middleware\cors.py", line 147, in simple_response
    await self.app(scope, receive, send)
  File "C:\Users\Razer\AppData\Local\Programs\Python\Python310\lib\site-packages\starlette\exceptions.py", line 82, in __call__
    raise exc
  File "C:\Users\Razer\AppData\Local\Programs\Python\Python310\lib\site-packages\starlette\exceptions.py", line 71, in __call__
    await self.app(scope, receive, sender)
  File "C:\Users\Razer\AppData\Local\Programs\Python\Python310\lib\site-packages\fastapi\middleware\asyncexitstack.py", line 21, in __call__
    raise e
  File "C:\Users\Razer\AppData\Local\Programs\Python\Python310\lib\site-packages\fastapi\middleware\asyncexitstack.py", line 18, in __call__
    await self.app(scope, receive, send)
  File "C:\Users\Razer\AppData\Local\Programs\Python\Python310\lib\site-packages\starlette\routing.py", line 656, in __call__
    await route.handle(scope, receive, send)
  File "C:\Users\Razer\AppData\Local\Programs\Python\Python310\lib\site-packages\starlette\routing.py", line 259, in handle
    await self.app(scope, receive, send)
  File "C:\Users\Razer\AppData\Local\Programs\Python\Python310\lib\site-packages\starlette\routing.py", line 61, in app
    response = await func(request)
  File "C:\Users\Razer\AppData\Local\Programs\Python\Python310\lib\site-packages\fastapi\routing.py", line 227, in app
    raw_response = await run_endpoint_function(
  File "C:\Users\Razer\AppData\Local\Programs\Python\Python310\lib\site-packages\fastapi\routing.py", line 162, in run_endpoint_function
    return await run_in_threadpool(dependant.call, **values)
  File "C:\Users\Razer\AppData\Local\Programs\Python\Python310\lib\site-packages\starlette\concurrency.py", line 39, in run_in_threadpool
    return await anyio.to_thread.run_sync(func, *args)
  File "C:\Users\Razer\AppData\Local\Programs\Python\Python310\lib\site-packages\anyio\to_thread.py", line 28, in run_sync
    return await get_asynclib().run_sync_in_worker_thread(func, *args, cancellable=cancellable,
  File "C:\Users\Razer\AppData\Local\Programs\Python\Python310\lib\site-packages\anyio\_backends\_asyncio.py", line 818, in run_sync_in_worker_thread
    return await future
  File "C:\Users\Razer\AppData\Local\Programs\Python\Python310\lib\site-packages\anyio\_backends\_asyncio.py", line 754, in run
    result = context.run(func, *args)
  File "C:\Users\Razer\Documents\GitHub\c5g8_esc\.\backend\routers\hotel.py", line 32, in serve_hotels
    hotel := database.generate_hotel(
  File "C:\Users\Razer\Documents\GitHub\c5g8_esc\.\backend\core\models\database.py", line 181, in generate_hotel
    hotel = requests.get(get_hotel_endpoint(hotel_id))
  File "C:\Users\Razer\AppData\Local\Programs\Python\Python310\lib\site-packages\requests\api.py", line 75, in get
    return request('get', url, params=params, **kwargs)
  File "C:\Users\Razer\AppData\Local\Programs\Python\Python310\lib\site-packages\requests\api.py", line 61, in request
    return session.request(method=method, url=url, **kwargs)
  File "C:\Users\Razer\AppData\Local\Programs\Python\Python310\lib\site-packages\requests\sessions.py", line 529, in request
    resp = self.send(prep, **send_kwargs)
  File "C:\Users\Razer\AppData\Local\Programs\Python\Python310\lib\site-packages\requests\sessions.py", line 645, in send
    r = adapter.send(request, **kwargs)
  File "C:\Users\Razer\AppData\Local\Programs\Python\Python310\lib\site-packages\requests\adapters.py", line 519, in send
    raise ConnectionError(e, request=request)
requests.exceptions.ConnectionError: HTTPSConnectionPool(host='hotelapi.loyalty.dev', port=443): Max retries exceeded with url: /api/hotels/Jot8 (Caused by NewConnectionError('<urllib3.connection.HTTPSConnection object at 0x000001F6603E38B0>: Failed to establish a new connection: [Errno 11001] getaddrinfo failed'))
